Workbook

Sheet GIVE_countries
A1: ISO3 | B1: country | C1: NetCDF_shape_file_mapping
A2: ABW | B2: Aruba | C2: =VLOOKUP(A2,shape_file_country!$A$3:$B$198,2,FALSE) -> #N/A | D2: This country and other N/A NOT mapped. Will need to apply global averages within GIVE
A3: AFG | B3: Afghanistan | C3: =VLOOKUP(A3,shape_file_country!$A$3:$B$198,2,FALSE) -> Afghanistan
A4: AGO | B4: Angola | C4: =VLOOKUP(A4,shape_file_country!$A$3:$B$198,2,FALSE) -> Angola
A5: ALB | B5: Albania | C5: =VLOOKUP(A5,shape_file_country!$A$3:$B$198,2,FALSE) -> Albania
A6: ARE | B6: United Arab Emirates | C6: =VLOOKUP(A6,shape_file_country!$A$3:$B$198,2,FALSE) -> United Arab Emirates
A7: ARG | B7: Argentina | C7: =VLOOKUP(A7,shape_file_country!$A$3:$B$198,2,FALSE) -> Argentina
A8: ARM | B8: Armenia | C8: =VLOOKUP(A8,shape_file_country!$A$3:$B$198,2,FALSE) -> Armenia
A9: AUS | B9: Australia | C9: =VLOOKUP(A9,shape_file_country!$A$3:$B$198,2,FALSE) -> Australia
A10: AUT | B10: Austria | C10: =VLOOKUP(A10,shape_file_country!$A$3:$B$198,2,FALSE) -> Austria
A11: AZE | B11: Azerbaijan | C11: =VLOOKUP(A11,shape_file_country!$A$3:$B$198,2,FALSE) -> Azerbaijan
A12: BDI | B12: Burundi | C12: =VLOOKUP(A12,shape_file_country!$A$3:$B$198,2,FALSE) -> Burundi
A13: BEL | B13: Belgium | C13: =VLOOKUP(A13,shape_file_country!$A$3:$B$198,2,FALSE) -> Belgium
A14: BEN | B14: Benin | C14: =VLOOKUP(A14,shape_file_country!$A$3:$B$198,2,FALSE) -> Benin
... A185: ZWE | B185: Zimbabwe | C185: =VLOOKUP(A185,shape_file_country!$A$3:$B$198,2,FALSE) -> Zimbabwe

Sheet shape_file_country
A1: Country codes associated with lat/lon point of NetCDF file. Country data from command ne_countries(scale = 10, returnclass = "sf")
A2: country_code_iso3 | B2: country_name
A3: ATA | B3: Antarctica
A4: NA | B4: NA
A5: CHL | B5: Chile
A6: ARG | B6: Argentina
A7: SGS | B7: S. Geo. and the Is.
A8: FLK | B8: Falkland Is.
A9: ATF | B9: Fr. S. Antarctic Lands
A10: NZL | B10: New Zealand
A11: AUS | B11: Australia
A12: URY | B12: Uruguay
A13: ZAF | B13: South Africa
... A76: TCD | B76: Chad
A77: -99 | B77: Somaliland
A78: IND | B78: India
A79: CRI | B79: Costa Rica
A80: SDN | B80: Sudan
A81: VNM | B81: Vietnam
A82: TTO | B82: Trinidad and Tobago
A83: MLI | B83: Mali
A84: BFA | B84: Burkina Faso
A85: MMR | B85: Myanmar
A86: KHM | B86: Cambodia
A87: NIC | B87: Nicaragua
A88: GNB | B88: Guinea-Bissau
A89: DJI | B89: Djibouti
... A118: ESH | B118: W. Sahara
A119: -99 | B119: Bir Tawil
A120: BGD | B120: Bangladesh
A121: BHS | B121: Bahamas
A122: EGY | B122: Egypt
A123: HKG | B123: Hong Kong
A124: TWN | B124: Taiwan
A125: ARE | B125: United Arab Emirates
A126: PAK | B126: Pakistan
A127: QAT | B127: Qatar
A128: IRN | B128: Iran
A129: JPN | B129: Japan
A130: NPL | B130: Nepal
...
